2020-03-23 05:37:30,502 ERROR: Exception on / [GET] [in /home/osboxes/PycharmProjects/microblog/venv/lib/python3.6/site-packages/flask/app.py:1891]
Traceback (most recent call last):
  File "/home/osboxes/PycharmProjects/microblog/venv/lib/python3.6/site-packages/flask/app.py", line 2446, in wsgi_app
    response = self.full_dispatch_request()
  File "/home/osboxes/PycharmProjects/microblog/venv/lib/python3.6/site-packages/flask/app.py", line 1951, in full_dispatch_request
    rv = self.handle_user_exception(e)
  File "/home/osboxes/PycharmProjects/microblog/venv/lib/python3.6/site-packages/flask/app.py", line 1820, in handle_user_exception
    reraise(exc_type, exc_value, tb)
  File "/home/osboxes/PycharmProjects/microblog/venv/lib/python3.6/site-packages/flask/_compat.py", line 39, in reraise
    raise value
  File "/home/osboxes/PycharmProjects/microblog/venv/lib/python3.6/site-packages/flask/app.py", line 1949, in full_dispatch_request
    rv = self.dispatch_request()
  File "/home/osboxes/PycharmProjects/microblog/venv/lib/python3.6/site-packages/flask/app.py", line 1935, in dispatch_request
    return self.view_functions[rule.endpoint](**req.view_args)
  File "/home/osboxes/PycharmProjects/microblog/venv/lib/python3.6/site-packages/flask_login/utils.py", line 272, in decorated_view
    return func(*args, **kwargs)
  File "/home/osboxes/PycharmProjects/microblog/app/routes.py", line 34, in index
    return render_template('index.html', title='Home', form=form, posts=posts.items, next_url=next_url, prev_url=prev_url)
  File "/home/osboxes/PycharmProjects/microblog/venv/lib/python3.6/site-packages/flask/templating.py", line 140, in render_template
    ctx.app,
  File "/home/osboxes/PycharmProjects/microblog/venv/lib/python3.6/site-packages/flask/templating.py", line 120, in _render
    rv = template.render(context)
  File "/home/osboxes/PycharmProjects/microblog/venv/lib/python3.6/site-packages/jinja2/environment.py", line 1090, in render
    self.environment.handle_exception()
  File "/home/osboxes/PycharmProjects/microblog/venv/lib/python3.6/site-packages/jinja2/environment.py", line 832, in handle_exception
    reraise(*rewrite_traceback_stack(source=source))
  File "/home/osboxes/PycharmProjects/microblog/venv/lib/python3.6/site-packages/jinja2/_compat.py", line 28, in reraise
    raise value.with_traceback(tb)
  File "/home/osboxes/PycharmProjects/microblog/app/templates/index.html", line 1, in top-level template code
    {% extends "base.html" %}
  File "/home/osboxes/PycharmProjects/microblog/venv/lib/python3.6/site-packages/jinja2/environment.py", line 832, in handle_exception
    reraise(*rewrite_traceback_stack(source=source))
  File "/home/osboxes/PycharmProjects/microblog/venv/lib/python3.6/site-packages/jinja2/_compat.py", line 28, in reraise
    raise value.with_traceback(tb)
  File "/home/osboxes/PycharmProjects/microblog/app/templates/base.html", line 13, in template
    <a href="{{ url_for('explore' }}">Explore</a>
jinja2.exceptions.TemplateSyntaxError: unexpected '}', expected ')'
2020-03-23 05:38:39,584 INFO: Microblog startup [in /home/osboxes/PycharmProjects/microblog/app/__init__.py:42]
2020-03-23 05:41:43,998 INFO: Microblog startup [in /home/osboxes/PycharmProjects/microblog/app/__init__.py:42]
2020-03-28 13:02:31,244 INFO: Microblog startup [in /home/osboxes/PycharmProjects/microblog/app/__init__.py:44]
2020-03-28 13:02:58,201 INFO: Microblog startup [in /home/osboxes/PycharmProjects/microblog/app/__init__.py:44]
2020-03-28 13:03:27,448 ERROR: Exception on /reset_password_request [POST] [in /home/osboxes/PycharmProjects/microblog/venv/lib/python3.6/site-packages/flask/app.py:1891]
Traceback (most recent call last):
  File "/home/osboxes/PycharmProjects/microblog/venv/lib/python3.6/site-packages/flask/app.py", line 2446, in wsgi_app
    response = self.full_dispatch_request()
  File "/home/osboxes/PycharmProjects/microblog/venv/lib/python3.6/site-packages/flask/app.py", line 1951, in full_dispatch_request
    rv = self.handle_user_exception(e)
  File "/home/osboxes/PycharmProjects/microblog/venv/lib/python3.6/site-packages/flask/app.py", line 1820, in handle_user_exception
    reraise(exc_type, exc_value, tb)
  File "/home/osboxes/PycharmProjects/microblog/venv/lib/python3.6/site-packages/flask/_compat.py", line 39, in reraise
    raise value
  File "/home/osboxes/PycharmProjects/microblog/venv/lib/python3.6/site-packages/flask/app.py", line 1949, in full_dispatch_request
    rv = self.dispatch_request()
  File "/home/osboxes/PycharmProjects/microblog/venv/lib/python3.6/site-packages/flask/app.py", line 1935, in dispatch_request
    return self.view_functions[rule.endpoint](**req.view_args)
  File "/home/osboxes/PycharmProjects/microblog/app/routes.py", line 98, in reset_password_request
    send_password_reset_email(user)
  File "/home/osboxes/PycharmProjects/microblog/app/email.py", line 17, in send_password_reset_email
    token = user.get_reset_password_token()
  File "/home/osboxes/PycharmProjects/microblog/app/models.py", line 65, in get_reset_password_token
    app.config['SECRET_KEY'], algorithm='HS256').decode('utf-8')
NameError: name 'app' is not defined
2020-03-28 13:05:34,258 INFO: Microblog startup [in /home/osboxes/PycharmProjects/microblog/app/__init__.py:44]
2020-03-28 13:06:15,838 INFO: Microblog startup [in /home/osboxes/PycharmProjects/microblog/app/__init__.py:44]
2020-03-28 13:06:22,106 ERROR: Exception on /reset_password_request [POST] [in /home/osboxes/PycharmProjects/microblog/venv/lib/python3.6/site-packages/flask/app.py:1891]
Traceback (most recent call last):
  File "/home/osboxes/PycharmProjects/microblog/venv/lib/python3.6/site-packages/flask/app.py", line 2446, in wsgi_app
    response = self.full_dispatch_request()
  File "/home/osboxes/PycharmProjects/microblog/venv/lib/python3.6/site-packages/flask/app.py", line 1951, in full_dispatch_request
    rv = self.handle_user_exception(e)
  File "/home/osboxes/PycharmProjects/microblog/venv/lib/python3.6/site-packages/flask/app.py", line 1820, in handle_user_exception
    reraise(exc_type, exc_value, tb)
  File "/home/osboxes/PycharmProjects/microblog/venv/lib/python3.6/site-packages/flask/_compat.py", line 39, in reraise
    raise value
  File "/home/osboxes/PycharmProjects/microblog/venv/lib/python3.6/site-packages/flask/app.py", line 1949, in full_dispatch_request
    rv = self.dispatch_request()
  File "/home/osboxes/PycharmProjects/microblog/venv/lib/python3.6/site-packages/flask/app.py", line 1935, in dispatch_request
    return self.view_functions[rule.endpoint](**req.view_args)
  File "/home/osboxes/PycharmProjects/microblog/app/routes.py", line 98, in reset_password_request
    send_password_reset_email(user)
  File "/home/osboxes/PycharmProjects/microblog/app/email.py", line 22, in send_password_reset_email
    html_body=render_template('email/reset_password.html', user=user, token=token))
  File "/home/osboxes/PycharmProjects/microblog/venv/lib/python3.6/site-packages/flask/templating.py", line 140, in render_template
    ctx.app,
  File "/home/osboxes/PycharmProjects/microblog/venv/lib/python3.6/site-packages/flask/templating.py", line 120, in _render
    rv = template.render(context)
  File "/home/osboxes/PycharmProjects/microblog/venv/lib/python3.6/site-packages/jinja2/environment.py", line 1090, in render
    self.environment.handle_exception()
  File "/home/osboxes/PycharmProjects/microblog/venv/lib/python3.6/site-packages/jinja2/environment.py", line 832, in handle_exception
    reraise(*rewrite_traceback_stack(source=source))
  File "/home/osboxes/PycharmProjects/microblog/venv/lib/python3.6/site-packages/jinja2/_compat.py", line 28, in reraise
    raise value.with_traceback(tb)
  File "/home/osboxes/PycharmProjects/microblog/app/templates/email/reset_password.html", line 4, in top-level template code
    <a href="{{ url_for('reset_password&#39', token=token, _external=True) }}">
  File "/home/osboxes/PycharmProjects/microblog/venv/lib/python3.6/site-packages/flask/helpers.py", line 370, in url_for
    return appctx.app.handle_url_build_error(error, endpoint, values)
  File "/home/osboxes/PycharmProjects/microblog/venv/lib/python3.6/site-packages/flask/app.py", line 2215, in handle_url_build_error
    reraise(exc_type, exc_value, tb)
  File "/home/osboxes/PycharmProjects/microblog/venv/lib/python3.6/site-packages/flask/_compat.py", line 39, in reraise
    raise value
  File "/home/osboxes/PycharmProjects/microblog/venv/lib/python3.6/site-packages/flask/helpers.py", line 358, in url_for
    endpoint, values, method=method, force_external=external
  File "/home/osboxes/PycharmProjects/microblog/venv/lib/python3.6/site-packages/werkzeug/routing.py", line 2179, in build
    raise BuildError(endpoint, values, method, self)
werkzeug.routing.BuildError: Could not build url for endpoint 'reset_password&#39' with values ['token']. Did you mean 'reset_password' instead?
2020-03-28 13:10:15,716 INFO: Microblog startup [in /home/osboxes/PycharmProjects/microblog/app/__init__.py:44]
